Workbook

Sheet Assumptions
A1: Assumptions: every input to the budget model (Dr. David Hartigan, Google Ads proposal, run date 2026-09-24)
A2: Legend: cells in blue text on a light yellow fill are inputs Kristina may change live on a call. Black cells are labels. The Tiers and Pilot Plan tabs are formulas only and recalculate from this tab.
A3: Low, base, and high are the values used by the Low, Base, and High columns of the Tiers tab. Every volume is modeled and low confidence (02_keyword_summary.md). National benchmarks (B1 to B3) are national, not Twin Cities figures.
A5: Input | B5: ID (source or assumption) | C5: Units | D5: Low | E5: Base | F5: High | G5: Notes
A6: 1. Demand ceilings: Tier 1 plus Tier 2 monthly searches by cluster (from 02_keywords.csv sums; base is the geometric mean of low and high, D51)
A7: Hip replacement: Tier 1 plus Tier 2 searches per month (metro) | B7: B63; D51 | C7: searches per month | D7: 800 | E7: 1400 | F7: 2500 | G7: Low and high are the metro ceilings in 02_keyword_summary.md (hip preservation: metro low to the O11 ring high, between metro and Minnesota). Base = geometric mean rounded to two significant figures (D51).
A8: Knee replacement: Tier 1 plus Tier 2 searches per month (metro) | B8: B63; D51 | C8: searches per month | D8: 1000 | E8: 1800 | F8: 3300 | G8: Low and high are the metro ceilings in 02_keyword_summary.md (hip preservation: metro low to the O11 ring high, between metro and Minnesota). Base = geometric mean rounded to two significant figures (D51).
A9: Hip preservation: Tier 1 plus Tier 2 searches per month (metro plus 60-mile ring (O11)) | B9: B63; O11; D51 | C9: searches per month | D9: 120 | E9: 270 | F9: 590 | G9: Low and high are the metro ceilings in 02_keyword_summary.md (hip preservation: metro low to the O11 ring high, between metro and Minnesota). Base = geometric mean rounded to two significant figures (D51).
A10: ACL reconstruction: Tier 1 plus Tier 2 searches per month (metro) | B10: B63; D51 | C10: searches per month | D10: 350 | E10: 620 | F10: 1100 | G10: Low and high are the metro ceilings in 02_keyword_summary.md (hip preservation: metro low to the O11 ring high, between metro and Minnesota). Base = geometric mean rounded to two significant figures (D51).
A11: Meniscus repair: Tier 1 plus Tier 2 searches per month (metro) | B11: B63; D51 | C11: searches per month | D11: 250 | E11: 450 | F11: 800 | G11: Low and high are the metro ceilings in 02_keyword_summary.md (hip preservation: metro low to the O11 ring high, between metro and Minnesota). Base = geometric mean rounded to two significant figures (D51).
A12: Rotator cuff repair: Tier 1 plus Tier 2 searches per month (metro) | B12: B63; D51 | C12: searches per month | D12: 270 | E12: 490 | F12: 880 | G12: Low and high are the metro ceilings in 02_keyword_summary.md (hip preservation: metro low to the O11 ring high, between metro and Minnesota). Base = geometric mean rounded to two significant figures (D51).
A13: 2. Tier 3 condition research monthly searches by cluster (from 02_keywords.csv; enter the model only through the Tier 3 inclusion share, section 5)
A14: Hip replacement: Tier 3 searches per month (metro) | B14: B63; B65; D51 | C14: searches per month | D14: 220 | E14: 390 | F14: 690 | G14: Sum of the Tier 3 rows in 02_keywords.csv for the metro; hip preservation high scaled to the ring per O11 and B53. Base = geometric mean (D51). Tier 3 clicks are discounted for AI Overviews (B65) through the inclusion share.
A15: Knee replacement: Tier 3 searches per month (metro) | B15: B63; B65; D51 | C15: searches per month | D15: 380 | E15: 680 | F15: 1200 | G15: Sum of the Tier 3 rows in 02_keywords.csv for the metro; hip preservation high scaled to the ring per O11 and B53. Base = geometric mean (D51). Tier 3 clicks are discounted for AI Overviews (B65) through the inclusion share.
A16: Hip preservation: Tier 3 searches per month (metro plus 60-mile ring (O11)) | B16: B63; B65; D51 | C16: searches per month | D16: 380 | E16: 800 | F16: 1700 | G16: Sum of the Tier 3 rows in 02_keywords.csv for the metro; hip preservation high scaled to the ring per O11 and B53. Base = geometric mean (D51). Tier 3 clicks are discounted for AI Overviews (B65) through the inclusion share.
A17: ACL reconstruction: Tier 3 searches per month (metro) | B17: B63; B65; D51 | C17: searches per month | D17: 680 | E17: 1200 | F17: 2100 | G17: Sum of the Tier 3 rows in 02_keywords.csv for the metro; hip preservation high scaled to the ring per O11 and B53. Base = geometric mean (D51). Tier 3 clicks are discounted for AI Overviews (B65) through the inclusion share.
A18: Meniscus repair: Tier 3 searches per month (metro) | B18: B63; B65; D51 | C18: searches per month | D18: 1100 | E18: 1900 | F18: 3300 | G18: Sum of the Tier 3 rows in 02_keywords.csv for the metro; hip preservation high scaled to the ring per O11 and B53. Base = geometric mean (D51). Tier 3 clicks are discounted for AI Overviews (B65) through the inclusion share.
A19: Rotator cuff repair: Tier 3 searches per month (metro) | B19: B63; B65; D51 | C19: searches per month | D19: 630 | E19: 1100 | F19: 1900 | G19: Sum of the Tier 3 rows in 02_keywords.csv for the metro; hip preservation high scaled to the ring per O11 and B53. Base = geometric mean (D51). Tier 3 clicks are discounted for AI Overviews (B65) through the inclusion share.
A20: 3. Query expansion and achievable impression share
A21: Phrase-match query expansion factor (eligible searches per listed keyword search) | B21: D12; D52 | C21: multiplier | D21: 1 | E21: 1.25 | F21: 1.5 | G21: Phrase match also serves for queries that include the meaning of the keyword (D12), so eligible searches exceed the keyword list volume. Low = no expansion beyond the list; replaced by the day 30 impression share report.
A22: Achievable search impression share on Tier 1 and Tier 2 terms if budget allowed | B22: D11; D13; D53 | C22: share of eligible impressions | D22: 0.4 | E22: 0.6 | F22: 0.75 | G22: A surgeon-level advertiser against hospital systems; blog benchmarks put high-intent non-brand campaigns at 60% to 80% (D11, low reliability). Observed from the impression share columns after launch (D13).
A23: 4. Click-through rate by budget tier (blended across the terms each tier runs)
A24: Pilot: search CTR | B24: B1; D54 | C24: clicks per impression | D24: 0.06 | E24: 0.08 | F24: 0.11 | G24: National physicians and surgeons CTR is 6.61% (B1, 2026). Pilot runs the tightest surgeon-seeking and procedure terms, so its CTR sits above the category; Growth and Full add broader terms and Tier 3 tests, which lower the blend (D54).
A25: Growth: search CTR | B25: B1; D54 | C25: clicks per impression | D25: 0.055 | E25: 0.075 | F25: 0.1 | G25: National physicians and surgeons CTR is 6.61% (B1, 2026). Pilot runs the tightest surgeon-seeking and procedure terms, so its CTR sits above the category; Growth and Full add broader terms and Tier 3 tests, which lower the blend (D54).
A26: Full coverage: search CTR | B26: B1; D54 | C26: clicks per impression | D26: 0.05 | E26: 0.07 | F26: 0.09 | G26: National physicians and surgeons CTR is 6.61% (B1, 2026). Pilot runs the tightest surgeon-seeking and procedure terms, so its CTR sits above the category; Growth and Full add broader terms and Tier 3 tests, which lower the blend (D54).
A27: 5. Tier 3 inclusion share by budget tier (share of Tier 3 searches added to the eligible pool after the AI Overview discount)
A28: Pilot: Tier 3 inclusion share | B28: B65; D55 | C28: share of Tier 3 searches | D28: 0 | E28: 0 | F28: 0 | G28: Pilot runs no Tier 3 terms. Growth adds arthritis treatment tests; Full adds cost and condition tests. Held equal across cases (a scope decision, not an uncertainty).
A29: Growth: Tier 3 inclusion share | B29: B65; D55 | C29: share of Tier 3 searches | D29: 0.2 | E29: 0.2 | F29: 0.2 | G29: Pilot runs no Tier 3 terms. Growth adds arthritis treatment tests; Full adds cost and condition tests. Held equal across cases (a scope decision, not an uncertainty).
A30: Full coverage: Tier 3 inclusion share | B30: B65; D55 | C30: share of Tier 3 searches | D30: 0.35 | E30: 0.35 | F30: 0.35 | G30: Pilot runs no Tier 3 terms. Growth adds arthritis treatment tests; Full adds cost and condition tests. Held equal across cases (a scope decision, not an uncertainty).
A31: 6. Cost per click by cluster and budget tier (dollars per click)
A32: Pilot: Hip replacement CPC | B32: B60; D64 | C32: dollars per click | D32: 7 | E32: 10 | F32: 16 | G32: Pilot: blend of Tier 1 ($7 to $22) and Tier 2 ($6 to $16) modeled CPCs (B60), leaning to Tier 1; volume-weighted CSV range is $5.6 to $15.2 for hip and knee, $4.4 to $5.2 low and $11 to $12.7 high for the other clusters. Not a Twin Cities figure; replaced by the first 30 days of auction data.
A33: Pilot: Knee replacement CPC | B33: B60; D64 | C33: dollars per click | D33: 7 | E33: 10 | F33: 16 | G33: Pilot: blend of Tier 1 ($7 to $22) and Tier 2 ($6 to $16) modeled CPCs (B60), leaning to Tier 1; volume-weighted CSV range is $5.6 to $15.2 for hip and knee, $4.4 to $5.2 low and $11 to $12.7 high for the other clusters. Not a Twin Cities figure; replaced by the first 30 days of auction data.
A34: Pilot: Hip preservation CPC | B34: B60; D64 | C34: dollars per click | D34: 5 | E34: 8 | F34: 13 | G34: Pilot: blend of Tier 1 ($7 to $22) and Tier 2 ($6 to $16) modeled CPCs (B60), leaning to Tier 1; volume-weighted CSV range is $5.6 to $15.2 for hip and knee, $4.4 to $5.2 low and $11 to $12.7 high for the other clusters. Not a Twin Cities figure; replaced by the first 30 days of auction data.
A35: Pilot: ACL reconstruction CPC | B35: B60; D64 | C35: dollars per click | D35: 5 | E35: 8 | F35: 13 | G35: Pilot: blend of Tier 1 ($7 to $22) and Tier 2 ($6 to $16) modeled CPCs (B60), leaning to Tier 1; volume-weighted CSV range is $5.6 to $15.2 for hip and knee, $4.4 to $5.2 low and $11 to $12.7 high for the other clusters. Not a Twin Cities figure; replaced by the first 30 days of auction data.
A36: Pilot: Meniscus repair CPC | B36: B60; D64 | C36: dollars per click | D36: 4 | E36: 7 | F36: 12 | G36: Pilot: blend of Tier 1 ($7 to $22) and Tier 2 ($6 to $16) modeled CPCs (B60), leaning to Tier 1; volume-weighted CSV range is $5.6 to $15.2 for hip and knee, $4.4 to $5.2 low and $11 to $12.7 high for the other clusters. Not a Twin Cities figure; replaced by the first 30 days of auction data.
A37: Pilot: Rotator cuff repair CPC | B37: B60; D64 | C37: dollars per click | D37: 5 | E37: 8 | F37: 13 | G37: Pilot: blend of Tier 1 ($7 to $22) and Tier 2 ($6 to $16) modeled CPCs (B60), leaning to Tier 1; volume-weighted CSV range is $5.6 to $15.2 for hip and knee, $4.4 to $5.2 low and $11 to $12.7 high for the other clusters. Not a Twin Cities figure; replaced by the first 30 days of auction data.
A38: Growth: Hip replacement CPC | B38: B60; D64 | C38: dollars per click | D38: 7.7 | E38: 11 | F38: 17.6 | G38: Growth = Pilot CPC x 1.1: reaching more of the auction needs higher bids and adds more competitive terms (D64). Not a Twin Cities figure; replaced by the first 30 days of auction data.
A39: Growth: Knee replacement CPC | B39: B60; D64 | C39: dollars per click | D39: 7.7 | E39: 11 | F39: 17.6 | G39: Growth = Pilot CPC x 1.1: reaching more of the auction needs higher bids and adds more competitive terms (D64). Not a Twin Cities figure; replaced by the first 30 days of auction data.
A40: Growth: Hip preservation CPC | B40: B60; D64 | C40: dollars per click | D40: 5.5 | E40: 8.8 | F40: 14.3 | G40: Growth = Pilot CPC x 1.1: reaching more of the auction needs higher bids and adds more competitive terms (D64). Not a Twin Cities figure; replaced by the first 30 days of auction data.
A41: Growth: ACL reconstruction CPC | B41: B60; D64 | C41: dollars per click | D41: 5.5 | E41: 8.8 | F41: 14.3 | G41: Growth = Pilot CPC x 1.1: reaching more of the auction needs higher bids and adds more competitive terms (D64). Not a Twin Cities figure; replaced by the first 30 days of auction data.
...

Sheet Keywords
A1: cluster | B1: procedure | C1: keyword | D1: intent_tier | E1: match_type | F1: searches_low | G1: searches_high | H1: cpc_low | I1: cpc_high | J1: competition | K1: priority | L1: source_id | M1: confidence | N1: notes
A2: hip_replacement | B2: computer-navigated total hip replacement | C2: hip replacement surgeon | D2: 1 | E2: phrase and exact | F2: 20 | G2: 67 | H2: 7 | I2: 20 | J2: high | K2: 1 | L2: B8;B56;B57;B60 | M2: low | N2: RFP seed. Surgeon-seeking share modeled at 3 to 8 pct of head term. National modeled 1800 to 4800.
A3: hip_replacement | B3: computer-navigated total hip replacement | C3: hip replacement doctor | D3: 1 | E3: phrase and exact | F3: 6 | G3: 21 | H3: 7 | I3: 18 | J3: high | K3: 1 | L3: B8;B56;B57;B60 | M3: low | N3: RFP seed. Doctor variant modeled at about 0.3x the surgeon variant. National modeled 500 to 1500.
A4: hip_replacement | B4: computer-navigated total hip replacement | C4: hip replacement surgeon near me | D4: 1 | E4: phrase and exact | F4: 16 | G4: 63 | H4: 8 | I4: 22 | J4: high | K4: 1 | L4: B7;B57;B60 | M4: low | N4: Near me variant modeled at 0.8 to 1.0x the surgeon term (B7 shows near me terms rival plain terms). National modeled 1500 to 4500.
A5: hip_replacement | B5: computer-navigated total hip replacement | C5: hip surgeon near me | D5: 1 | E5: phrase | F5: 16 | G5: 56 | H5: 8 | I5: 22 | J5: high | K5: 1 | L5: B7;B57;B60 | M5: low | N5: Broader than replacement; add negatives for arthroscopy-only intent if it drifts. National modeled 1500 to 4000.
A6: hip_replacement | B6: computer-navigated total hip replacement | C6: best hip replacement surgeon | D6: 1 | E6: phrase | F6: 9 | G6: 35 | H6: 7 | I6: 20 | J6: high | K6: 1 | L6: B57;B60 | M6: low | N6: Includes best ... near me close variants. National modeled 800 to 2500.
A7: hip_replacement | B7: computer-navigated total hip replacement | C7: hip surgeon Edina | D7: 1 | E7: phrase | F7: 5 | G7: 20 | H7: 6 | I7: 16 | J7: medium | K7: 1 | L7: B58;B60 | M7: low | N7: Geo-modified; whole volume is local and counted as-is in every geography. Modeled 5 to 20 per month (B58).
A8: hip_replacement | B8: computer-navigated total hip replacement | C8: hip replacement surgeon Maple Grove | D8: 1 | E8: phrase | F8: 5 | G8: 20 | H8: 6 | I8: 16 | J8: medium | K8: 1 | L8: B58;B60 | M8: low | N8: Geo-modified; whole volume is local and counted as-is in every geography. Modeled 5 to 20 per month (B58).
A9: hip_replacement | B9: computer-navigated total hip replacement | C9: hip surgeon Plymouth MN | D9: 1 | E9: phrase | F9: 5 | G9: 20 | H9: 6 | I9: 16 | J9: medium | K9: 1 | L9: B58;B60 | M9: low | N9: Geo-modified; whole volume is local and counted as-is in every geography. Modeled 5 to 20 per month (B58).
A10: hip_replacement | B10: computer-navigated total hip replacement | C10: hip replacement surgeon Minneapolis | D10: 1 | E10: phrase | F10: 10 | G10: 60 | H10: 7 | I10: 18 | J10: high | K10: 1 | L10: B58;B60 | M10: low | N10: Geo-modified; whole volume is local and counted as-is in every geography. Modeled 10 to 60 per month (B58).
A11: hip_replacement | B11: computer-navigated total hip replacement | C11: hip pain doctor | D11: 1 | E11: phrase | F11: 16 | G11: 56 | H11: 5 | I11: 12 | J11: medium | K11: 2 | L11: B57;B60 | M11: low | N11: Doctor-seeking on a condition; mixed intent (non-surgical). National modeled 1500 to 4000.
A12: hip_replacement | B12: computer-navigated total hip replacement | C12: hip pain specialist near me | D12: 1 | E12: phrase | F12: 11 | G12: 42 | H12: 5 | I12: 12 | J12: medium | K12: 2 | L12: B57;B60 | M12: low | N12: Mixed intent; route to hip hub page. National modeled 1000 to 3000.
A13: hip_replacement | B13: computer-navigated total hip replacement | C13: hip replacement | D13: 2 | E13: phrase | F13: 440 | G13: 1300 | H13: 5 | I13: 14 | J13: high | K13: 2 | L13: B8;B56;B60 | M13: low | N13: Head term; research-heavy. Phrase match with heavy negatives; hold until Tier 1 data exists. National modeled 4x to 9x the B8 anchor.
... A110: rotator_cuff | B110: rotator cuff repair | C110: rotator cuff surgery recovery | D110: 3 | E110: exact | F110: 55 | G110: 170 | H110: 2 | I110: 5 | J110: low | K110: 3 | L110: B13;B59;B60 | M110: low | N110: Judgment call: recovery is the most searched rotator cuff topic (B13) but mostly post-op; negative in Tier 1 and 2. Listed to size it. National modeled 5000 to 12000.

Sheet Tiers
A1: Tiers: live formulas only, all inputs from the Assumptions tab. Monthly figures. Cost per consult is computed from deployed spend, never typed.
A2: Low column = low demand, low CPC, low rates (fewest consults, highest cost per consult). High column = the opposite. Deployed spend falls below budget when the demand cap binds.
A3: Tier | B3: Case | C3: Budget $ | D3: Deployed spend $ | E3: Unspent budget $ | F3: Clicks | G3: Blended CPC $ | H3: Contacts | I3: Qualified inquiries | J3: Consults booked | K3: Consults attended | L3: Cost per qualified inquiry | M3: Cost per consult booked | N3: Cost per consult attended
A4: Pilot | B4: Low | C4: =C23 -> 3000 | D4: =J23 -> 316.8 | E4: =K23 -> 2683.2 | F4: =H23 -> 46.08 | G4: =D23 -> 6.875 | H4: =L23 -> 2.7648 | I4: =M23 -> 0.82944 | J4: =N23 -> 0.41472 | K4: =O23 -> 0.31104 | L4: =P23 -> 381.94444 | M4: =Q23 -> 763.88889 | N4: =R23 -> 1018.5185
A5: Pilot | B5: Base | C5: =C33 -> 3000 | D5: =J33 -> 2049.6 | E5: =K33 -> 950.4 | F5: =H33 -> 208.2 | G5: =D33 -> 9.8443804 | H5: =L33 -> 20.82 | I5: =M33 -> 9.369 | J5: =N33 -> 6.08985 | K5: =O33 -> 5.1763725 | L5: =P33 -> 218.76401 | M5: =Q33 -> 336.56001 | N5: =R33 -> 395.95296
A6: Pilot | B6: High | C6: =C43 -> 3000 | D6: =J43 -> 3000 | E6: =K43 -> 0 | F6: =H43 -> 193.99038 | G6: =D43 -> 15.464684 | H6: =L43 -> 27.158654 | I6: =M43 -> 16.295192 | J6: =N43 -> 13.036154 | K6: =O43 -> 11.993262 | L6: =P43 -> 184.10338 | M6: =Q43 -> 230.12923 | N6: =R43 -> 250.14046
A7: Growth | B7: Low | C7: =C53 -> 6000 | D7: =J53 -> 501.182 | E7: =K53 -> 5498.818 | F7: =H53 -> 76.296 | G7: =D53 -> 6.5689158 | H7: =L53 -> 4.57776 | I7: =M53 -> 1.373328 | J7: =N53 -> 0.686664 | K7: =O53 -> 0.514998 | L7: =P53 -> 364.93977 | M7: =Q53 -> 729.87953 | N7: =R53 -> 973.17271
A8: Growth | B8: Base | C8: =C63 -> 6000 | D8: =J63 -> 3461.9062 | E8: =K63 -> 2538.0938 | F8: =H63 -> 351.225 | G8: =D63 -> 9.8566624 | H8: =L63 -> 35.1225 | I8: =M63 -> 15.805125 | J8: =N63 -> 10.273331 | K8: =O63 -> 8.7323316 | L8: =P63 -> 219.03694 | M8: =Q63 -> 336.97991 | N8: =R63 -> 396.44695
A9: Growth | B9: High | C9: =C73 -> 6000 | D9: =J73 -> 6000 | E9: =K73 -> 0 | F9: =H73 -> 372.9021 | G9: =D73 -> 16.090014 | H9: =L73 -> 52.206294 | I9: =M73 -> 31.323776 | J9: =N73 -> 25.059021 | K9: =O73 -> 23.054299 | L9: =P73 -> 191.54779 | M9: =Q73 -> 239.43473 | N9: =R73 -> 260.25514
A10: Full coverage | B10: Low | C10: =C83 -> 9000 | D10: =J83 -> 558.42 | E10: =K83 -> 8441.58 | F10: =H83 -> 79.53 | G10: =D83 -> 7.0215013 | H10: =L83 -> 4.7718 | I10: =M83 -> 1.43154 | J10: =N83 -> 0.71577 | K10: =O83 -> 0.5368275 | L10: =P83 -> 390.08341 | M10: =Q83 -> 780.16681 | N10: =R83 -> 1040.2224
A11: Full coverage | B11: Base | C11: =C93 -> 9000 | D11: =J93 -> 3986.01 | E11: =K93 -> 5013.99 | F11: =H93 -> 375.61125 | G11: =D93 -> 10.612062 | H11: =L93 -> 37.561125 | I11: =M93 -> 16.902506 | J11: =N93 -> 10.986629 | K11: =O93 -> 9.3386347 | L11: =P93 -> 235.82361 | M11: =Q93 -> 362.80555 | N11: =R93 -> 426.83006
A12: Full coverage | B12: High | C12: =C103 -> 9000 | D12: =J103 -> 9000 | E12: =K103 -> 0 | F12: =H103 -> 515.38462 | G12: =D103 -> 17.462687 | H12: =L103 -> 72.153846 | I12: =M103 -> 43.292308 | J12: =N103 -> 34.633846 | K12: =O103 -> 31.863138 | L12: =P103 -> 207.88913 | M12: =Q103 -> 259.86141 | N12: =R103 -> 282.45805
A14: Detail by tier, case, and cluster
A15: Pilot tier, Low case
A16: Cluster | B16: Share of spend | C16: Budget $ | D16: CPC $ | E16: Eligible searches per month | F16: Click cap (searches x IS x CTR) | G16: Uncapped clicks (budget / CPC) | H16: Clicks (min of cap and uncapped) | I16: Cap binds? | J16: Deployed spend $ | K16: Unspent budget $ | L16: Contacts | M16: Qualified inquiries | N16: Consults booked | O16: Consults attended | P16: Cost per qualified inquiry | Q16: Cost per consult booked | R16: Cost per consult attended
A17: Hip replacement | B17: =Assumptions!$D$60 -> 0.45 | C17: =Assumptions!$D$56*B17 -> 1350 | D17: =Assumptions!$D$32 -> 7 | E17: =(Assumptions!$D$7+Assumptions!$D$14*Assumptions!$D$28)*Assumptions!$D$21 -> 800 | F17: =E17*Assumptions!$D$22*Assumptions!$D$24 -> 19.2 | G17: =IFERROR(C17/D17,0) -> 192.85714 | H17: =MIN(F17,G17) -> 19.2 | I17: =IF(G17>F17,"Yes","No") -> Yes | J17: =H17*D17 -> 134.4 | K17: =C17-J17 -> 1215.6 | L17: =H17*Assumptions!$D$51 -> 1.152 | M17: =L17*Assumptions!$D$52 -> 0.3456 | N17: =M17*Assumptions!$D$53 -> 0.1728 | O17: =N17*Assumptions!$D$54 -> 0.1296 | P17: =IF(M17>0,J17/M17,0) -> 388.88889 | Q17: =IF(N17>0,J17/N17,0) -> 777.77778 | R17: =IF(O17>0,J17/O17,0) -> 1037.037
A18: Knee replacement | B18: =Assumptions!$D$61 -> 0.4 | C18: =Assumptions!$D$56*B18 -> 1200 | D18: =Assumptions!$D$33 -> 7 | E18: =(Assumptions!$D$8+Assumptions!$D$15*Assumptions!$D$28)*Assumptions!$D$21 -> 1000 | F18: =E18*Assumptions!$D$22*Assumptions!$D$24 -> 24 | G18: =IFERROR(C18/D18,0) -> 171.42857 | H18: =MIN(F18,G18) -> 24 | I18: =IF(G18>F18,"Yes","No") -> Yes | J18: =H18*D18 -> 168 | K18: =C18-J18 -> 1032 | L18: =H18*Assumptions!$D$51 -> 1.44 | M18: =L18*Assumptions!$D$52 -> 0.432 | N18: =M18*Assumptions!$D$53 -> 0.216 | O18: =N18*Assumptions!$D$54 -> 0.162 | P18: =IF(M18>0,J18/M18,0) -> 388.88889 | Q18: =IF(N18>0,J18/N18,0) -> 777.77778 | R18: =IF(O18>0,J18/O18,0) -> 1037.037
A19: Hip preservation | B19: =Assumptions!$D$62 -> 0.15 | C19: =Assumptions!$D$56*B19 -> 450 | D19: =Assumptions!$D$34 -> 5 | E19: =(Assumptions!$D$9+Assumptions!$D$16*Assumptions!$D$28)*Assumptions!$D$21 -> 120 | F19: =E19*Assumptions!$D$22*Assumptions!$D$24 -> 2.88 | G19: =IFERROR(C19/D19,0) -> 90 | H19: =MIN(F19,G19) -> 2.88 | I19: =IF(G19>F19,"Yes","No") -> Yes | J19: =H19*D19 -> 14.4 | K19: =C19-J19 -> 435.6 | L19: =H19*Assumptions!$D$51 -> 0.1728 | M19: =L19*Assumptions!$D$52 -> 0.05184 | N19: =M19*Assumptions!$D$53 -> 0.02592 | O19: =N19*Assumptions!$D$54 -> 0.01944 | P19: =IF(M19>0,J19/M19,0) -> 277.77778 | Q19: =IF(N19>0,J19/N19,0) -> 555.55556 | R19: =IF(O19>0,J19/O19,0) -> 740.74074
A20: ACL reconstruction | B20: =Assumptions!$D$63 -> 0 | C20: =Assumptions!$D$56*B20 -> 0 | D20: =Assumptions!$D$35 -> 5 | E20: =(Assumptions!$D$10+Assumptions!$D$17*Assumptions!$D$28)*Assumptions!$D$21 -> 350 | F20: =E20*Assumptions!$D$22*Assumptions!$D$24 -> 8.4 | G20: =IFERROR(C20/D20,0) -> 0 | H20: =MIN(F20,G20) -> 0 | I20: =IF(G20>F20,"Yes","No") -> No | J20: =H20*D20 -> 0 | K20: =C20-J20 -> 0 | L20: =H20*Assumptions!$D$51 -> 0 | M20: =L20*Assumptions!$D$52 -> 0 | N20: =M20*Assumptions!$D$53 -> 0 | O20: =N20*Assumptions!$D$54 -> 0 | P20: =IF(M20>0,J20/M20,0) -> 0 | Q20: =IF(N20>0,J20/N20,0) -> 0 | R20: =IF(O20>0,J20/O20,0) -> 0
A21: Meniscus repair | B21: =Assumptions!$D$64 -> 0 | C21: =Assumptions!$D$56*B21 -> 0 | D21: =Assumptions!$D$36 -> 4 | E21: =(Assumptions!$D$11+Assumptions!$D$18*Assumptions!$D$28)*Assumptions!$D$21 -> 250 | F21: =E21*Assumptions!$D$22*Assumptions!$D$24 -> 6 | G21: =IFERROR(C21/D21,0) -> 0 | H21: =MIN(F21,G21) -> 0 | I21: =IF(G21>F21,"Yes","No") -> No | J21: =H21*D21 -> 0 | K21: =C21-J21 -> 0 | L21: =H21*Assumptions!$D$51 -> 0 | M21: =L21*Assumptions!$D$52 -> 0 | N21: =M21*Assumptions!$D$53 -> 0 | O21: =N21*Assumptions!$D$54 -> 0 | P21: =IF(M21>0,J21/M21,0) -> 0 | Q21: =IF(N21>0,J21/N21,0) -> 0 | R21: =IF(O21>0,J21/O21,0) -> 0
A22: Rotator cuff repair | B22: =Assumptions!$D$65 -> 0 | C22: =Assumptions!$D$56*B22 -> 0 | D22: =Assumptions!$D$37 -> 5 | E22: =(Assumptions!$D$12+Assumptions!$D$19*Assumptions!$D$28)*Assumptions!$D$21 -> 270 | F22: =E22*Assumptions!$D$22*Assumptions!$D$24 -> 6.48 | G22: =IFERROR(C22/D22,0) -> 0 | H22: =MIN(F22,G22) -> 0 | I22: =IF(G22>F22,"Yes","No") -> No | J22: =H22*D22 -> 0 | K22: =C22-J22 -> 0 | L22: =H22*Assumptions!$D$51 -> 0 | M22: =L22*Assumptions!$D$52 -> 0 | N22: =M22*Assumptions!$D$53 -> 0 | O22: =N22*Assumptions!$D$54 -> 0 | P22: =IF(M22>0,J22/M22,0) -> 0 | Q22: =IF(N22>0,J22/N22,0) -> 0 | R22: =IF(O22>0,J22/O22,0) -> 0
A23: Total | B23: =SUM(B17:B22) -> 1 | C23: =SUM(C17:C22) -> 3000 | D23: =IF(H23>0,J23/H23,0) -> 6.875 | E23: =SUM(E17:E22) -> 2790 | F23: =SUM(F17:F22) -> 66.96 | G23: =SUM(G17:G22) -> 454.28571 | H23: =SUM(H17:H22) -> 46.08 | I23: =IF(COUNTIF(I17:I22,"Yes")>0,"Yes, some","No") -> Yes, some | J23: =SUM(J17:J22) -> 316.8 | K23: =SUM(K17:K22) -> 2683.2 | L23: =SUM(L17:L22) -> 2.7648 | M23: =SUM(M17:M22) -> 0.82944 | N23: =SUM(N17:N22) -> 0.41472 | O23: =SUM(O17:O22) -> 0.31104 | P23: =IF(M23>0,J23/M23,0) -> 381.94444 | Q23: =IF(N23>0,J23/N23,0) -> 763.88889 | R23: =IF(O23>0,J23/O23,0) -> 1018.5185
A25: Pilot tier, Base case
A26: Cluster | B26: Share of spend | C26: Budget $ | D26: CPC $ | E26: Eligible searches per month | F26: Click cap (searches x IS x CTR) | G26: Uncapped clicks (budget / CPC) | H26: Clicks (min of cap and uncapped) | I26: Cap binds? | J26: Deployed spend $ | K26: Unspent budget $ | L26: Contacts | M26: Qualified inquiries | N26: Consults booked | O26: Consults attended | P26: Cost per qualified inquiry | Q26: Cost per consult booked | R26: Cost per consult attended
A27: Hip replacement | B27: =Assumptions!$E$60 -> 0.45 | C27: =Assumptions!$E$56*B27 -> 1350 | D27: =Assumptions!$E$32 -> 10 | E27: =(Assumptions!$E$7+Assumptions!$E$14*Assumptions!$E$28)*Assumptions!$E$21 -> 1750 | F27: =E27*Assumptions!$E$22*Assumptions!$E$24 -> 84 | G27: =IFERROR(C27/D27,0) -> 135 | H27: =MIN(F27,G27) -> 84 | I27: =IF(G27>F27,"Yes","No") -> Yes | J27: =H27*D27 -> 840 | K27: =C27-J27 -> 510 | L27: =H27*Assumptions!$E$51 -> 8.4 | M27: =L27*Assumptions!$E$52 -> 3.78 | N27: =M27*Assumptions!$E$53 -> 2.457 | O27: =N27*Assumptions!$E$54 -> 2.08845 | P27: =IF(M27>0,J27/M27,0) -> 222.22222 | Q27: =IF(N27>0,J27/N27,0) -> 341.88034 | R27: =IF(O27>0,J27/O27,0) -> 402.21217
A28: Knee replacement | B28: =Assumptions!$E$61 -> 0.4 | C28: =Assumptions!$E$56*B28 -> 1200 | D28: =Assumptions!$E$33 -> 10 | E28: =(Assumptions!$E$8+Assumptions!$E$15*Assumptions!$E$28)*Assumptions!$E$21 -> 2250 | F28: =E28*Assumptions!$E$22*Assumptions!$E$24 -> 108 | G28: =IFERROR(C28/D28,0) -> 120 | H28: =MIN(F28,G28) -> 108 | I28: =IF(G28>F28,"Yes","No") -> Yes | J28: =H28*D28 -> 1080 | K28: =C28-J28 -> 120 | L28: =H28*Assumptions!$E$51 -> 10.8 | M28: =L28*Assumptions!$E$52 -> 4.86 | N28: =M28*Assumptions!$E$53 -> 3.159 | O28: =N28*Assumptions!$E$54 -> 2.68515 | P28: =IF(M28>0,J28/M28,0) -> 222.22222 | Q28: =IF(N28>0,J28/N28,0) -> 341.88034 | R28: =IF(O28>0,J28/O28,0) -> 402.21217
A29: Hip preservation | B29: =Assumptions!$E$62 -> 0.15 | C29: =Assumptions!$E$56*B29 -> 450 | D29: =Assumptions!$E$34 -> 8 | E29: =(Assumptions!$E$9+Assumptions!$E$16*Assumptions!$E$28)*Assumptions!$E$21 -> 337.5 | F29: =E29*Assumptions!$E$22*Assumptions!$E$24 -> 16.2 | G29: =IFERROR(C29/D29,0) -> 56.25 | H29: =MIN(F29,G29) -> 16.2 | I29: =IF(G29>F29,"Yes","No") -> Yes | J29: =H29*D29 -> 129.6 | K29: =C29-J29 -> 320.4 | L29: =H29*Assumptions!$E$51 -> 1.62 | M29: =L29*Assumptions!$E$52 -> 0.729 | N29: =M29*Assumptions!$E$53 -> 0.47385 | O29: =N29*Assumptions!$E$54 -> 0.4027725 | P29: =IF(M29>0,J29/M29,0) -> 177.77778 | Q29: =IF(N29>0,J29/N29,0) -> 273.50427 | R29: =IF(O29>0,J29/O29,0) -> 321.76973
A30: ACL reconstruction | B30: =Assumptions!$E$63 -> 0 | C30: =Assumptions!$E$56*B30 -> 0 | D30: =Assumptions!$E$35 -> 8 | E30: =(Assumptions!$E$10+Assumptions!$E$17*Assumptions!$E$28)*Assumptions!$E$21 -> 775 | F30: =E30*Assumptions!$E$22*Assumptions!$E$24 -> 37.2 | G30: =IFERROR(C30/D30,0) -> 0 | H30: =MIN(F30,G30) -> 0 | I30: =IF(G30>F30,"Yes","No") -> No | J30: =H30*D30 -> 0 | K30: =C30-J30 -> 0 | L30: =H30*Assumptions!$E$51 -> 0 | M30: =L30*Assumptions!$E$52 -> 0 | N30: =M30*Assumptions!$E$53 -> 0 | O30: =N30*Assumptions!$E$54 -> 0 | P30: =IF(M30>0,J30/M30,0) -> 0 | Q30: =IF(N30>0,J30/N30,0) -> 0 | R30: =IF(O30>0,J30/O30,0) -> 0
A31: Meniscus repair | B31: =Assumptions!$E$64 -> 0 | C31: =Assumptions!$E$56*B31 -> 0 | D31: =Assumptions!$E$36 -> 7 | E31: =(Assumptions!$E$11+Assumptions!$E$18*Assumptions!$E$28)*Assumptions!$E$21 -> 562.5 | F31: =E31*Assumptions!$E$22*Assumptions!$E$24 -> 27 | G31: =IFERROR(C31/D31,0) -> 0 | H31: =MIN(F31,G31) -> 0 | I31: =IF(G31>F31,"Yes","No") -> No | J31: =H31*D31 -> 0 | K31: =C31-J31 -> 0 | L31: =H31*Assumptions!$E$51 -> 0 | M31: =L31*Assumptions!$E$52 -> 0 | N31: =M31*Assumptions!$E$53 -> 0 | O31: =N31*Assumptions!$E$54 -> 0 | P31: =IF(M31>0,J31/M31,0) -> 0 | Q31: =IF(N31>0,J31/N31,0) -> 0 | R31: =IF(O31>0,J31/O31,0) -> 0
A32: Rotator cuff repair | B32: =Assumptions!$E$65 -> 0 | C32: =Assumptions!$E$56*B32 -> 0 | D32: =Assumptions!$E$37 -> 8 | E32: =(Assumptions!$E$12+Assumptions!$E$19*Assumptions!$E$28)*Assumptions!$E$21 -> 612.5 | F32: =E32*Assumptions!$E$22*Assumptions!$E$24 -> 29.4 | G32: =IFERROR(C32/D32,0) -> 0 | H32: =MIN(F32,G32) -> 0 | I32: =IF(G32>F32,"Yes","No") -> No | J32: =H32*D32 -> 0 | K32: =C32-J32 -> 0 | L32: =H32*Assumptions!$E$51 -> 0 | M32: =L32*Assumptions!$E$52 -> 0 | N32: =M32*Assumptions!$E$53 -> 0 | O32: =N32*Assumptions!$E$54 -> 0 | P32: =IF(M32>0,J32/M32,0) -> 0 | Q32: =IF(N32>0,J32/N32,0) -> 0 | R32: =IF(O32>0,J32/O32,0) -> 0
A33: Total | B33: =SUM(B27:B32) -> 1 | C33: =SUM(C27:C32) -> 3000 | D33: =IF(H33>0,J33/H33,0) -> 9.8443804 | E33: =SUM(E27:E32) -> 6287.5 | F33: =SUM(F27:F32) -> 301.8 | G33: =SUM(G27:G32) -> 311.25 | H33: =SUM(H27:H32) -> 208.2 | I33: =IF(COUNTIF(I27:I32,"Yes")>0,"Yes, some","No") -> Yes, some | J33: =SUM(J27:J32) -> 2049.6 | K33: =SUM(K27:K32) -> 950.4 | L33: =SUM(L27:L32) -> 20.82 | M33: =SUM(M27:M32) -> 9.369 | N33: =SUM(N27:N32) -> 6.08985 | O33: =SUM(O27:O32) -> 5.1763725 | P33: =IF(M33>0,J33/M33,0) -> 218.76401 | Q33: =IF(N33>0,J33/N33,0) -> 336.56001 | R33: =IF(O33>0,J33/O33,0) -> 395.95296
A35: Pilot tier, High case
A36: Cluster | B36: Share of spend | C36: Budget $ | D36: CPC $ | E36: Eligible searches per month | F36: Click cap (searches x IS x CTR) | G36: Uncapped clicks (budget / CPC) | H36: Clicks (min of cap and uncapped) | I36: Cap binds? | J36: Deployed spend $ | K36: Unspent budget $ | L36: Contacts | M36: Qualified inquiries | N36: Consults booked | O36: Consults attended | P36: Cost per qualified inquiry | Q36: Cost per consult booked | R36: Cost per consult attended
A37: Hip replacement | B37: =Assumptions!$F$60 -> 0.45 | C37: =Assumptions!$F$56*B37 -> 1350 | D37: =Assumptions!$F$32 -> 16 | E37: =(Assumptions!$F$7+Assumptions!$F$14*Assumptions!$F$28)*Assumptions!$F$21 -> 3750 | F37: =E37*Assumptions!$F$22*Assumptions!$F$24 -> 309.375 | G37: =IFERROR(C37/D37,0) -> 84.375 | H37: =MIN(F37,G37) -> 84.375 | I37: =IF(G37>F37,"Yes","No") -> No | J37: =H37*D37 -> 1350 | K37: =C37-J37 -> 0 | L37: =H37*Assumptions!$F$51 -> 11.8125 | M37: =L37*Assumptions!$F$52 -> 7.0875 | N37: =M37*Assumptions!$F$53 -> 5.67 | O37: =N37*Assumptions!$F$54 -> 5.2164 | P37: =IF(M37>0,J37/M37,0) -> 190.47619 | Q37: =IF(N37>0,J37/N37,0) -> 238.09524 | R37: =IF(O37>0,J37/O37,0) -> 258.79917
A38: Knee replacement | B38: =Assumptions!$F$61 -> 0.4 | C38: =Assumptions!$F$56*B38 -> 1200 | D38: =Assumptions!$F$33 -> 16 | E38: =(Assumptions!$F$8+Assumptions!$F$15*Assumptions!$F$28)*Assumptions!$F$21 -> 4950 | F38: =E38*Assumptions!$F$22*Assumptions!$F$24 -> 408.375 | G38: =IFERROR(C38/D38,0) -> 75 | H38: =MIN(F38,G38) -> 75 | I38: =IF(G38>F38,"Yes","No") -> No | J38: =H38*D38 -> 1200 | K38: =C38-J38 -> 0 | L38: =H38*Assumptions!$F$51 -> 10.5 | M38: =L38*Assumptions!$F$52 -> 6.3 | N38: =M38*Assumptions!$F$53 -> 5.04 | O38: =N38*Assumptions!$F$54 -> 4.6368 | P38: =IF(M38>0,J38/M38,0) -> 190.47619 | Q38: =IF(N38>0,J38/N38,0) -> 238.09524 | R38: =IF(O38>0,J38/O38,0) -> 258.79917
A39: Hip preservation | B39: =Assumptions!$F$62 -> 0.15 | C39: =Assumptions!$F$56*B39 -> 450 | D39: =Assumptions!$F$34 -> 13 | E39: =(Assumptions!$F$9+Assumptions!$F$16*Assumptions!$F$28)*Assumptions!$F$21 -> 885 | F39: =E39*Assumptions!$F$22*Assumptions!$F$24 -> 73.0125 | G39: =IFERROR(C39/D39,0) -> 34.615385 | H39: =MIN(F39,G39) -> 34.615385 | I39: =IF(G39>F39,"Yes","No") -> No | J39: =H39*D39 -> 450 | K39: =C39-J39 -> 0 | L39: =H39*Assumptions!$F$51 -> 4.8461538 | M39: =L39*Assumptions!$F$52 -> 2.9076923 | N39: =M39*Assumptions!$F$53 -> 2.3261538 | O39: =N39*Assumptions!$F$54 -> 2.1400615 | P39: =IF(M39>0,J39/M39,0) -> 154.7619 | Q39: =IF(N39>0,J39/N39,0) -> 193.45238 | R39: =IF(O39>0,J39/O39,0) -> 210.27433
A40: ACL reconstruction | B40: =Assumptions!$F$63 -> 0 | C40: =Assumptions!$F$56*B40 -> 0 | D40: =Assumptions!$F$35 -> 13 | E40: =(Assumptions!$F$10+Assumptions!$F$17*Assumptions!$F$28)*Assumptions!$F$21 -> 1650 | F40: =E40*Assumptions!$F$22*Assumptions!$F$24 -> 136.125 | G40: =IFERROR(C40/D40,0) -> 0 | H40: =MIN(F40,G40) -> 0 | I40: =IF(G40>F40,"Yes","No") -> No | J40: =H40*D40 -> 0 | K40: =C40-J40 -> 0 | L40: =H40*Assumptions!$F$51 -> 0 | M40: =L40*Assumptions!$F$52 -> 0 | N40: =M40*Assumptions!$F$53 -> 0 | O40: =N40*Assumptions!$F$54 -> 0 | P40: =IF(M40>0,J40/M40,0) -> 0 | Q40: =IF(N40>0,J40/N40,0) -> 0 | R40: =IF(O40>0,J40/O40,0) -> 0
A41: Meniscus repair | B41: =Assumptions!$F$64 -> 0 | C41: =Assumptions!$F$56*B41 -> 0 | D41: =Assumptions!$F$36 -> 12 | E41: =(Assumptions!$F$11+Assumptions!$F$18*Assumptions!$F$28)*Assumptions!$F$21 -> 1200 | F41: =E41*Assumptions!$F$22*Assumptions!$F$24 -> 99 | G41: =IFERROR(C41/D41,0) -> 0 | H41: =MIN(F41,G41) -> 0 | I41: =IF(G41>F41,"Yes","No") -> No | J41: =H41*D41 -> 0 | K41: =C41-J41 -> 0 | L41: =H41*Assumptions!$F$51 -> 0 | M41: =L41*Assumptions!$F$52 -> 0 | N41: =M41*Assumptions!$F$53 -> 0 | O41: =N41*Assumptions!$F$54 -> 0 | P41: =IF(M41>0,J41/M41,0) -> 0 | Q41: =IF(N41>0,J41/N41,0) -> 0 | R41: =IF(O41>0,J41/O41,0) -> 0
A42: Rotator cuff repair | B42: =Assumptions!$F$65 -> 0 | C42: =Assumptions!$F$56*B42 -> 0 | D42: =Assumptions!$F$37 -> 13 | E42: =(Assumptions!$F$12+Assumptions!$F$19*Assumptions!$F$28)*Assumptions!$F$21 -> 1320 | F42: =E42*Assumptions!$F$22*Assumptions!$F$24 -> 108.9 | G42: =IFERROR(C42/D42,0) -> 0 | H42: =MIN(F42,G42) -> 0 | I42: =IF(G42>F42,"Yes","No") -> No | J42: =H42*D42 -> 0 | K42: =C42-J42 -> 0 | L42: =H42*Assumptions!$F$51 -> 0 | M42: =L42*Assumptions!$F$52 -> 0 | N42: =M42*Assumptions!$F$53 -> 0 | O42: =N42*Assumptions!$F$54 -> 0 | P42: =IF(M42>0,J42/M42,0) -> 0 | Q42: =IF(N42>0,J42/N42,0) -> 0 | R42: =IF(O42>0,J42/O42,0) -> 0
A43: Total | B43: =SUM(B37:B42) -> 1 | C43: =SUM(C37:C42) -> 3000 | D43: =IF(H43>0,J43/H43,0) -> 15.464684 | E43: =SUM(E37:E42) -> 13755 | F43: =SUM(F37:F42) -> 1134.7875 | G43: =SUM(G37:G42) -> 193.99038 | H43: =SUM(H37:H42) -> 193.99038 | I43: =IF(COUNTIF(I37:I42,"Yes")>0,"Yes, some","No") -> No | J43: =SUM(J37:J42) -> 3000 | K43: =SUM(K37:K42) -> 0 | L43: =SUM(L37:L42) -> 27.158654 | M43: =SUM(M37:M42) -> 16.295192 | N43: =SUM(N37:N42) -> 13.036154 | O43: =SUM(O37:O42) -> 11.993262 | P43: =IF(M43>0,J43/M43,0) -> 184.10338 | Q43: =IF(N43>0,J43/N43,0) -> 230.12923 | R43: =IF(O43>0,J43/O43,0) -> 250.14046
...

Sheet Pilot Plan
A1: 90-day pilot plan with decision gates (numbers reference the Assumptions and Tiers tabs by formula)
A2: Practice-reported qualified inquiries and consults (03_measurement_compliance.md) are the steering measures; Google Ads conversions are the bidding signal only (C57).
A3: Gate or period | B3: Timing | C3: What happens | D3: Owner | E3: Decision rule | F3: Threshold or figure | G3: Units | H3: Source or ID
A4: Pre-launch | B4: Days -14 to 0 | C4: Practice confirms intake phone hours (placeholder Monday to Friday, 8 am to 5 pm Central), the navigation and robotic systems and facilities (O12), and whether TCO marketing must approve. Vendor BAAs signed (call tracking, forms); DNI number and form event built; landing pages live; negative list loaded; campaigns built but paused. | D4: Humanus, practice | E4: Launch only when tracking test calls and forms appear in the vendor dashboard. | H4: C42 to C48; C51; O12
A5: Launch | B5: Day 1 | C5: Pilot goes live: hip replacement, knee replacement, hip preservation campaigns. Monthly cap: | D5: Humanus | E5: Daily budget = monthly cap / days per month. | F5: =Assumptions!$E$56 -> 3000 | G5: dollars per month | H5: D60
A6: Launch | B6: Day 1 | C6: Daily budget across the three campaigns. | D6: Humanus | E6: Set per campaign in proportion to the allocation shares. | F6: =Assumptions!$E$56/Assumptions!$E$80 -> 98.684211 | G6: dollars per day | H6: D60; D62
A7: Launch | B7: Days 1 to 30 | C7: Bidding: Maximize clicks with a maximum CPC bid limit while conversion tracking accrues data. | D7: Humanus | E7: Bid limit = high-case Pilot hip replacement CPC. | F7: =Assumptions!$F$32 -> 16 | G7: dollars per click | H7: B60; D64; C16
A8: Gate 1: tracking verified | B8: Day 14 | C8: Test and live calls of 60 seconds or more and form submissions appear in the vendor log and in Google Ads as primary conversions; call reporting off; no PHI in any tag. | D8: Humanus, practice compliance | E8: If any check fails, pause until fixed. | H8: C13; C17 to C20; C51
A9: Gate 2: search terms and lead quality | B9: Day 30 | C9: Search term report reviewed; negatives added; NQ-code tally from intake reviewed (counts only). Compare recorded contacts with the modeled range. | D9: Humanus, practice intake | E9: Contacts in month one, modeled low case. | F9: =Tiers!$H$4 -> 2.7648 | G9: contacts per month | H9: Tiers
A10: Gate 2: search terms and lead quality | B10: Day 30 | C10: Same review. | D10: Humanus | E10: Contacts in month one, modeled base case. | F10: =Tiers!$H$5 -> 20.82 | G10: contacts per month | H10: Tiers
A11: Gate 2: search terms and lead quality | B11: Day 30 | C11: Same review. | D11: Humanus | E11: Contacts in month one, modeled high case. | F11: =Tiers!$H$6 -> 27.158654 | G11: contacts per month | H11: Tiers
A12: Gate 2: search terms and lead quality | B12: Day 30 | C12: Lead quality: qualified inquiries as a share of contacts, from the NQ-code tally. | D12: Practice intake | E12: Below the low-case rate for the month: tighten match types and negatives before any budget change. | F12: =Assumptions!$D$52 -> 0.3 | G12: share of contacts | H12: D57
A13: Gate 2: demand check | B13: Day 30 | C13: Search impression share, lost to budget, and lost to rank read from Google Ads for each campaign. | D13: Humanus | E13: Lost to rank above lost to budget means the demand cap is real: hold the cap. Lost to budget above 20% means demand exceeds the model: raise the cap in $500 steps at day 60. | F13: =Assumptions!$E$22 -> 0.6 | G13: modeled achievable impression share | H13: D11; D13; D53
A14: Bidding switch | B14: Day 30 to 45 | C14: Switch to Maximize conversions (no target) once verified primary conversions in the last 30 days reach the floor. | D14: Humanus | E14: Minimum primary conversions in 30 days. | F14: =Assumptions!$E$81 -> 15 | G14: conversions | H14: C16; D63
A15: Gate 3: phase-in and bidding | B15: Day 60 | C15: Decide whether the sports medicine campaign (ACL, meniscus, rotator cuff) starts. Start it if the launch campaigns are demand-bound (lost to budget under 10%) and cost per qualified inquiry is at or below the base case; otherwise hold to day 90. | D15: Humanus, practice | E15: Sports medicine monthly budget at the Growth tier. | F15: =Assumptions!$E$57*(Assumptions!$E$69+Assumptions!$E$70+Assumptions!$E$71) -> 1680 | G15: dollars per month | H15: O13; D61
A16: Gate 3: phase-in and bidding | B16: Day 60 | C16: Target CPA only if the conversion floor is met for the trailing 30 days; otherwise stay on Maximize conversions. | D16: Humanus | E16: Minimum primary conversions in 30 days. | F16: =Assumptions!$E$82 -> 30 | G16: conversions | H16: C14; C15; C58
A17: Gate 4: scale, hold, or cut | B17: Day 60 to 90 | C17: Practice-reported cost per qualified inquiry (deployed spend / qualified inquiries, two-month average). | D17: Humanus, practice | E17: Scale: at or below the base-case figure and lost to budget above 10%. Move to the Growth tier. | F17: =Tiers!$L$5 -> 218.76401 | G17: dollars per qualified inquiry | H17: Tiers
A18: Gate 4: scale, hold, or cut | B18: Day 60 to 90 | C18: Same measure. | D18: Humanus, practice | E18: Hold: between the base-case and low-case figures. Keep the Pilot cap, fix intake, pages, and terms. | F18: =Tiers!$L$4 -> 381.94444 | G18: dollars per qualified inquiry | H18: Tiers
A19: Gate 4: scale, hold, or cut | B19: Day 60 to 90 | C19: Same measure. | D19: Humanus, practice | E19: Cut: above the low-case figure for two consecutive months. Reduce the cap to the deployed spend of the best cluster, or pause the weakest campaign. | F19: =Tiers!$L$4 -> 381.94444 | G19: dollars per qualified inquiry | H19: Tiers
A20: Gate 4: scale, hold, or cut | B20: Day 60 to 90 | C20: Practice-reported cost per consult attended (deployed spend / consults attended, two-month average). | D20: Humanus, practice | E20: Scale threshold: base case. | F20: =Tiers!$N$5 -> 395.95296 | G20: dollars per consult | H20: Tiers
A21: Gate 4: scale, hold, or cut | B21: Day 60 to 90 | C21: Same measure. | D21: Humanus, practice | E21: Cut threshold: low case (two consecutive months above it). | F21: =Tiers!$N$4 -> 1018.5185 | G21: dollars per consult | H21: Tiers
A22: Gate 4: scale, hold, or cut | B22: Day 90 | C22: If scaling, the next monthly cap is the Growth tier. | D22: Practice decides | E22: Growth tier monthly ad spend. | F22: =Assumptions!$E$57 -> 6000 | G22: dollars per month | H22: D60
A23: Gate 4: scale, hold, or cut | B23: Day 90 | C23: Growth tier base-case consults attended per month, for comparison. | D23: Humanus | E23: Modeled, not promised. | F23: =Tiers!$K$8 -> 8.7323316 | G23: consults per month | H23: Tiers
A24: 90-day totals | B24: Days 1 to 90 | C24: Pilot spend cap over the pilot. | D24: Humanus | E24: Monthly cap x months. | F24: =Assumptions!$E$56*Assumptions!$E$79 -> 9000 | G24: dollars | H24: D60; D62
A25: 90-day totals | B25: Days 1 to 90 | C25: Deployed spend over the pilot, low case (demand-bound). | D25: Humanus | E25: Monthly deployed x months. | F25: =Tiers!$D$4*Assumptions!$D$79 -> 950.4 | G25: dollars | H25: Tiers
A26: 90-day totals | B26: Days 1 to 90 | C26: Deployed spend over the pilot, base case. | D26: Humanus | E26: Monthly deployed x months. | F26: =Tiers!$D$5*Assumptions!$E$79 -> 6148.8 | G26: dollars | H26: Tiers
A27: 90-day totals | B27: Days 1 to 90 | C27: Deployed spend over the pilot, high case. | D27: Humanus | E27: Monthly deployed x months. | F27: =Tiers!$D$6*Assumptions!$F$79 -> 9000 | G27: dollars | H27: Tiers
A28: 90-day totals | B28: Days 1 to 90 | C28: Qualified inquiries over the pilot, low / base / high. | D28: Practice reports | E28: Monthly x months. | F28: =Tiers!$I$4*Assumptions!$D$79 -> 2.48832 | G28: qualified inquiries (low) | H28: Tiers
A29: 90-day totals | B29: Days 1 to 90 | C29: Same. | D29: Practice reports | E29: Monthly x months. | F29: =Tiers!$I$5*Assumptions!$E$79 -> 28.107 | G29: qualified inquiries (base) | H29: Tiers
A30: 90-day totals | B30: Days 1 to 90 | C30: Same. | D30: Practice reports | E30: Monthly x months. | F30: =Tiers!$I$6*Assumptions!$F$79 -> 48.885577 | G30: qualified inquiries (high) | H30: Tiers
A31: 90-day totals | B31: Days 1 to 90 | C31: Consults attended over the pilot, low / base / high. | D31: Practice reports | E31: Monthly x months. | F31: =Tiers!$K$4*Assumptions!$D$79 -> 0.93312 | G31: consults attended (low) | H31: Tiers
A32: 90-day totals | B32: Days 1 to 90 | C32: Same. | D32: Practice reports | E32: Monthly x months. | F32: =Tiers!$K$5*Assumptions!$E$79 -> 15.529117 | G32: consults attended (base) | H32: Tiers
A33: 90-day totals | B33: Days 1 to 90 | C33: Same. | D33: Practice reports | E33: Monthly x months. | F33: =Tiers!$K$6*Assumptions!$F$79 -> 35.979785 | G33: consults attended (high) | H33: Tiers
